Workbook

Sheet Inputs
A1: Parameter | B1: Subclass | C1: Value | D1: Units | E1: Description | F1: Notes
A2: DqA_wheel | B2: aero | C2: 0.25 | D2: - | E2: Wheel drag per frontal area (D/q/A)
A3: DqA_strut | B3: aero | C3: 0.3 | D3: - | E3: Strut drag per frontal area (D/q/A)
A4: CD_0_misc_factor | B4: aero | C4: 0.1 | D4: - | E4: Misc. drag as fraction of component CD_0
A5: CL_max | B5: aero | C5: 1.43 | D5: - | E5: Max lift coefficient (stall)
A6: CL_C | B6: aero | C6: 0.3 | D6: - | E6: Design cruise lift coefficient
A7: CL_0 | B7: aero | C7: 0.43 | D7: - | E7: Lift coefficient at zero AoA
A8: CM_ac_w | B8: aero | C8: -0.08 | D8: - | E8: Wing pitching moment about AC
A9: CM_0_Wing | B9: aero | C9: -0.08 | D9: -
A10: Airfoil_Alpha_Stall | B10: aero | C10: 15.8 | D10: deg | E10: Airfoil stall angle
A11: e_t | B11: aero | C11: 0.65 | D11: - | E11: Oswald efficiency, horizontal tail
A12: crosswind_ratio | B12: aero | C12: 0.33 | D12: - | E12: Crosswind ratio
A13: roll_rate_target_dps | B13: aero | C13: 120 | D13: deg/s | E13: Target roll rate
A14: CM_EquivalentRotate | B14: aero | C14: 0.1 | D14: - | E14: Extra pitch moment for takeoff rotation
A15: Q_wing | B15: aero | C15: 1 | D15: - | E15: Interference factor, wing
A16: Q_hstab | B16: aero | C16: 1.05 | D16: - | E16: Interference factor, horizontal tail
A17: Q_vstab | B17: aero | C17: 1.05 | D17: - | E17: Interference factor, vertical tail
A18: S_wet_factor | B18: aero | C18: 1.02 | D18: - | E18: Wetted area per side / planform area
A19: g | B19: env | C19: 9.81 | D19: m/s^2 | E19: Gravitational acceleration
A20: rho | B20: env | C20: 1.225 | D20: kg/m^3 | E20: Air density (sea level)
A21: visc | B21: env | C21: 1.796e-05 | D21: Pa-s | E21: Air dynamic viscosity
... A86: V_batt | B86: prop | C86: 14.8 | D86: V | E86: Battery voltage (4S)
A87: prop_file | B87: prop | C87: PER3_10x7E.txt | D87: - | E87: APC propeller data file
A88: rho_battery | B88: prop | C88: 527000 | D88: J/kg | E88: Battery specific energy
A89: useableCapacity | B89: prop | C89: 0.8 | D89: - | E89: Usable fraction of battery capacity
A90: temp_derate | B90: prop | C90: 0.7 | D90: - | E90: Battery temperature derating
A91: T_static_actual | B91: prop | C91: =2.085*9.81 -> 20.45385 | D91: N
A92: linkage_ratio_aileron | B92: controls | C92: 1 | D92: - | E92: Aileron servo-arm / control-horn mechanical advantage
A93: linkage_ratio_elevator | B93: controls | C93: 1.2 | D93: - | E93: Elevator servo-arm / control-horn mechanical advantage
A94: linkage_ratio_rudder | B94: controls | C94: 1 | D94: - | E94: Rudder servo-arm / control-horn mechanical advantage
A95: linkage_efficiency | B95: controls | C95: 0.85 | D95: - | E95: Pushrod/linkage mechanical efficiency (friction losses); applies to all three surfaces
A96: V_servo_rail | B96: controls | C96: 5.5 | D96: V | E96: Servo rail (BEC output) voltage used to evaluate torque at the actual operating voltage -- matches the MG90S stall-torque rating quoted at 5.5V
A97: CL_max_neg | B97: aero | C97: -0.66 | D97: - | E97: Negative (inverted-flight) max lift coefficient
A98: x_spar | B98: structures | C98: 0.25 | D98: - | E98: Wing spar/shear-center location, fraction of chord aft of LE
A99: eta_h | B99: structures | C99: 1 | D99: - | E99: Horizontal tail dynamic-pressure ratio q_tail/q_freestream
A100: eta_v | B100: structures | C100: 1 | D100: - | E100: Vertical tail (fin) dynamic-pressure ratio
A101: CL_max_tail | B101: structures | C101: 1 | D101: - | E101: Max lift coefficient of the tail's symmetric section (NACA 0010)
A102: D_fus_tail | B102: structures | C102: 0.0127 | D102: m | E102: Fuselage/tailboom depth at the fin root
A103: x_LE_wing | B103: structures | C103: 0.295 | D103: m | E103: Fuselage station of the wing's MAC leading edge, from the nose
... A119: gear_strut_length | B119: geometry | C119: 0.148 | D119: m | E119: MAIN STRUT BEAM LENGTH - USED FOR STRESS MARGINS
...

Sheet Outputs
A1: Parameter | B1: Subclass | C1: Value | D1: Units | E1: Description | F1: Source | H1: Written by writeOutputs.m on 2026-10-15 10:50
A2: CL_TO | B2: aero | C2: 0.3 | D2: - | E2: Takeoff CL before rotation, no flaps, same as cruise | F2: Calculated
A3: CL_R | B3: aero | C3: 1.1818182 | D3: - | E3: Rotation CL | F3: Calculated
A4: e_wing | B4: aero | C4: 0.92582241 | D4: - | E4: Oswald efficiency, Sadraey eqn 5.27a | F4: Calculated
A5: K_wing | B5: aero | C5: 0.080941856 | D5: - | E5: Induced drag factor | F5: Calculated
A6: K_hstab | B6: aero | C6: 0.19588301 | D6: - | E6: H-stab induced drag factor | F6: Calculated
A7: CD_0 | B7: aero | C7: 0.031335226 | F7: Calculated
A8: CD_C | B8: aero | C8: 0.038619993 | D8: - | E8: Cruise CD | F8: Calculated
A9: CD_TO | B9: aero | C9: 0.038619993 | D9: - | E9: Takeoff CD | F9: Calculated
A10: CD_G | B10: aero | C10: 0.023619993 | D10: - | E10: Ground roll CD, Sadraey eqn 4.67a | F10: Calculated
A11: L_D_C | B11: aero | C11: 7.7679973 | D11: - | E11: L/D at cruise | F11: Calculated
A12: L_D_max | B12: aero | C12: 9.9281198 | D12: - | E12: Max L/D of parabolic polar | F12: Calculated
A13: CL_Alpha_Tail | B13: aero | C13: 3.019855 | F13: Calculated
A14: CL_Alpha_Wing | B14: aero | C14: 3.9888877 | F14: Calculated
A15: de_da | B15: aero | C15: 0.59783681 | F15: Calculated
A16: CL_Alpha | B16: aero | C16: 5.2033622 | F16: Calculated
A17: CM_0 | B17: aero | C17: -0.096561354 | F17: Calculated
A18: tau_e | B18: aero | C18: 0.66074595 | F18: Calculated
A19: tau_a | B19: aero | C19: 0.60899778 | F19: Calculated
A20: CL_Alpha_VT | B20: aero | C20: 1.575327 | F20: Calculated
A21: tau_r | B21: aero | C21: 0.66074595 | F21: Calculated
A22: Cn_beta_VT | B22: aero | C22: 0.12602616 | F22: Calculated
A23: CL_ground_attitude | B23: aero | C23: 0.7805017 | F23: Calculated
A24: S_wing | B24: geometry | C24: 0.50145311 | D24: m^2 | E24: Wing area from design wing loading | F24: Calculated
A25: c_wing | B25: geometry | C25: 0.35313599 | D25: m | E25: Wing chord, area excludes fuselage section | F25: Calculated
A26: AR | B26: geometry | C26: 4.2476554 | D26: - | E26: Wing aspect ratio | F26: Calculated
A27: S_hstab | B27: geometry | C27: 0.085247028 | D27: m^2 | E27: H-stab area from area ratio | F27: Calculated
A28: span_hstab | B28: geometry | C28: 0.46164659 | D28: m | E28: H-stab span | F28: Calculated
A29: c_hstab | B29: geometry | C29: 0.18465863 | D29: m | E29: H-stab chord | F29: Calculated
A30: V_H | B30: geometry | C30: 0.38512076 | D30: - | E30: Horizontal tail volume coefficient | F30: Calculated
A31: S_v | B31: geometry | C31: 0.075217966 | D31: m^2 | E31: Total fin area from volume coefficient, fin arm = l_t | F31: Calculated
A32: S_fin | B32: geometry | C32: 0.075217966 | D32: m^2 | E32: Area per fin | F32: Calculated
A33: span_vstab | B33: geometry | C33: 0.28369565 | D33: m | E33: Fin span | F33: Calculated
A34: c_vstab | B34: geometry | C34: 0.26513612 | D34: m | E34: Fin chord | F34: Calculated
A35: x_cg_fwd | B35: geometry | C35: 0.028568191 | F35: Calculated
A36: x_cg_aft | B36: geometry | C36: 0.23237691 | F36: Calculated
A37: x_n | B37: geometry | C37: 0.36148522 | F37: Calculated
A38: x_cg_design | B38: geometry | C38: 0.21148522 | F38: Calculated
A39: MTOM | B39: performance | C39: 4.8546282 | F39: Overwritten input (Sheet1 value: 6)
A40: V_C | B40: performance | C40: 22.737784 | D40: m/s | E40: Cruise speed from design CL_C | F40: Calculated
...

Sheet MassBudget
A1: Component | B1: Mass_g | C1: X_m | D1: Z_m
A2: Propeller+spinner | B2: 25.9 | C2: 0 | D2: 0.06
A3: Motor | B3: 210 | C3: 0.022 | D3: 0.06
A4: Motor mount/firewall | B4: 74.6 | C4: 0.07 | D4: 0.056
A5: ESC | B5: 96.2 | C5: 0.136 | D5: 0.018
A6: Tail wheel | B6: 9 | C6: 1.254 | D6: -0.022
A7: Battery | B7: 451 | C7: 0.172 | D7: 0.049
A8: Flight controller/avionics | B8: 119.9 | C8: 0.437 | D8: 0.053
A9: Wiring + connectors | B9: 44.7 | C9: 0.565 | D9: 0.087
A10: Misc electronics | B10: 0.05 | C10: 0.332 | D10: 0.125
A11: Servo, aileron 1 | B11: 20.7 | C11: 0.462 | D11: 0.146
A12: Servo, aileron 2 | B12: 20.7 | C12: 0.462 | D12: 0.146
A13: Payload cube | B13: 520 | C13: 0.327 | D13: 0.032
... A20: V-tail (spar+foam) | B20: 13.9 | C20: 1.205 | D20: 0.188

Sheet Hinge Moments
A1: Control-Surface Hinge Moments - Thin-Airfoil (Glauert) Theory
A2: Geometry linked live from the Sheet1 tab. Inviscid 2-D theory typically over-predicts the real hinge moment by ~2x - conservative for servo sizing.
A4: PARAMETER | B4: AILERON | C4: ELEVATOR | D4: RUDDER
A5: Reference (root) chord, c (m) | B5: =(Inputs!C19*Inputs!C77/Inputs!C72)/(Inputs!C25-Inputs!C26) -> 0.4363232 | C5: 0.196 | D5: 0.196 | F5: Ch_alpha, Ch_delta from closed-form thin-airfoil (Glauert) flap theory, verified
A6: Control-surface chord fraction, Ef = cf/c | B6: =Inputs!C57 -> 0.25 | C6: =Inputs!C53 -> 0.3 | D6: =Inputs!C55 -> 0.3 | F6: against an independent numerical vortex-panel solution to 4 sig. figs.
A7: Control-surface chord, cf = Ef*c (m) | B7: =B6*B5 -> 0.1090808 | C7: =C6*C5 -> 0.0588 | D7: =D6*D5 -> 0.0588 | F7: Yellow cells are NOT linked to Sheet1 -- check/edit them:
A8: Control-surface span, bf (m) | B8: =(Inputs!C59-Inputs!C58)*Inputs!C25/2 -> 0.225 | C8: 0.539 | D8: 0.243 | F8: - c_hstab, c_vstab, span_hstab, span_vstab, and V_C (cruise speed) are not defined in Sheet1; literal values carried over from the old sheet -- verify/update manually.
A9: Max deflection, delta_max (deg) | B9: =Inputs!C60 -> 15 | C9: =Inputs!C54 -> 30 | D9: =Inputs!C56 -> 30 | F9: - alpha assumption per surface defaults to 0 deg (pure control deflection case);
A10: Local AoA assumed for this case, alpha (deg) | B10: 0 | C10: 1 | D10: 0 | F10: raise it for combined maneuver cases (e.g. elevator at high AoA).
A11: Design airspeed for this case, V (m/s) | B11: 23 | C11: 23 | D11: 23 | F11: - V_design defaults to V_C (cruise, not in Sheet1); consider a higher design/dive speed if known.
A12: Air density, rho (kg/m^3) | B12: =Inputs!C20 -> 1.225 | C12: =Inputs!C20 -> 1.225 | D12: =Inputs!C20 -> 1.225 | F12: Theory is inviscid/2-D and typically over-predicts real hinge moment ~2x --
A13: Extra servo safety margin factor (x) | B13: 1 | C13: 1 | D13: 1 | F13: conservative (safe) for servo torque sizing, but state that factor in the report.
A14: Linkage ratio, servo arm / control horn (mechanical advantage) | B14: =Inputs!C92 -> 1 | C14: =Inputs!C93 -> 1.2 | D14: =Inputs!C94 -> 1 | F14: Servo torque scales by (linkage ratio / efficiency): a longer servo arm vs. horn cuts required torque;
A15: Linkage efficiency, eta_linkage (friction losses) | B15: =Inputs!C95 -> 0.85 | C15: =Inputs!C95 -> 0.85 | D15: =Inputs!C95 -> 0.85 | F15: friction losses in the linkage mean the servo must output more torque than the ideal case.
A16: THIN-AIRFOIL DERIVATION
A17: theta_f = ACOS(2*Ef-1) (rad) | B17: =ACOS(2*B6-1) -> 2.0943951 | C17: =ACOS(2*C6-1) -> 1.9823132 | D17: =ACOS(2*D6-1) -> 1.9823132
A18: X = pi - theta_f | B18: =PI()-B17 -> 1.0471976 | C18: =PI()-C17 -> 1.1592795 | D18: =PI()-D17 -> 1.1592795
A19: Ch_alpha (floating tendency, per rad) | B19: =-(B18*(COS(B17)-0.5)+SIN(B17)*(1-COS(B17)/2))/B6^2 -> -0.56534726 | C19: =-(C18*(COS(C17)-0.5)+SIN(C17)*(1-COS(C17)/2))/C6^2 -> -0.62740705 | D19: =-(D18*(COS(D17)-0.5)+SIN(D17)*(1-COS(D17)/2))/D6^2 -> -0.62740705
A20: Ch_delta (restoring tendency, per rad) | B20: =-(B18^2*(COS(B17)-0.5)+B18*SIN(B17)+SIN(B17)^2/2)/(PI()*B6^2) -> -0.94360786 | C20: =-(C18^2*(COS(C17)-0.5)+C18*SIN(C17)+SIN(C17)^2/2)/(PI()*C6^2) -> -0.96540266 | D20: =-(D18^2*(COS(D17)-0.5)+D18*SIN(D17)+SIN(D17)^2/2)/(PI()*D6^2) -> -0.96540266
A21: RESULTING HINGE MOMENT (worst case: alpha & delta_max together)
A22: alpha (rad) | B22: =RADIANS(B10) -> 0 | C22: =RADIANS(C10) -> 0.017453293 | D22: =RADIANS(D10) -> 0
A23: delta_max (rad) | B23: =RADIANS(B9) -> 0.26179939 | C23: =RADIANS(C9) -> 0.52359878 | D23: =RADIANS(D9) -> 0.52359878
A24: Ch = Ch_alpha*alpha + Ch_delta*delta_max | B24: =B19*B22+B20*B23 -> -0.24703596 | C24: =C19*C22+C20*C23 -> -0.51643397 | D24: =D19*D22+D20*D23 -> -0.50548365
A25: Dynamic pressure, q = 0.5*rho*V^2 (Pa) | B25: =0.5*B12*B11^2 -> 324.0125 | C25: =0.5*C12*C11^2 -> 324.0125 | D25: =0.5*D12*D11^2 -> 324.0125
A26: Control-surface area, Sf = cf*bf (m^2) | B26: =B7*B8 -> 0.02454318 | C26: =C7*C8 -> 0.0316932 | D26: =D7*D8 -> 0.0142884
A27: Hinge moment, H = Ch*q*Sf*cf (N*m) | B27: =B24*B25*B26*B7 -> -0.2142896 | C27: =C24*C25*C26*C7 -> -0.3118315 | D27: =D24*D25*D26*D7 -> -0.1376036
A28: ... with safety margin, |H|*margin (N*m) | B28: =ABS(B27)*B13 -> 0.2142896 | C28: =ABS(C27)*C13 -> 0.3118315 | D28: =ABS(D27)*D13 -> 0.1376036
A29: ... in servo units (oz-in) | B29: =B28*B14/B15*141.612 -> 35.701152 | C29: =C28*C14/C15*141.612 -> 62.342234 | D29: =D28*D14/D15*141.612 -> 22.925084
A30: COMPARE TO XFLR5 (paste your sweep results here)
A31: XFLR5 Ch at same alpha, delta_max
A32: Ratio: thin-airfoil / XFLR5 | B32: =IF(B31="","",B24/B31) | C32: =IF(C31="","",C24/C31) | D32: =IF(D31="","",D24/D31)

Sheet Sheet1
C109: 11.941543 | F109: COMPUTED each run by MaxPayloadSweep.m = 1.25x the baseline self-consistent stall speed -- not read back in as an input, edit LANDING_SPEED_RATIO in that script instead.
